Workbook
Name xadd1: 'Conveyance Voucher'!#REF!

Sheet Front Page
A1: Ranks Petroleum Limited
A2: Petty Cash Bill Breakdown | C2: Bill Duration | D2: 21.12.2024- 31.12.2024
A3: WH/Depot | B3: Cumilla | C3: Month: December-2024 | D3: Bill No: Cum/65/December'2024
A4: Sl. No. | B4: Purpose | C4: Amount (Tk.) | D4: Purpose
A5: 1 | B5: B2B- IPP | C5: ='1. B2B- IPP'!M4 -> 0
A6: 2 | B6: B2C | C6: ='2. B2C'!L4 -> 33350 | D6: Cost: Transport,,Food,Conveyance
A7: 3 | B7: B2B- Non Power | C7: ='3. B2B-Non Power'!L4 -> 0
A8: 4 | B8: Goods Transfer (Sending) | C8: ='4. Goods Sending Expense'!L4 -> 0
A9: 5 | B9: Goods Transfer (Receiving) | C9: ='5. Goods Receiving Expense'!L4 -> 1090 | D9: Cost: Conveyance,food
A10: 6 | B10: Warehouse Maintenance | C10: ='6.WH-Depot Maintenance'!D3 -> 40 | D10: courier
A11: 7 | B11: Utilities | C11: ='7. Utilities'!F2 -> 0
A12: 8 | B12: Printing | C12: ='8. Printing'!E2 -> 0
A13: 9 | B13: Stationary | C13: ='9. Stationary'!E2 -> 0
A14: 10 | B14: Delivery Van Fuel & Lubricant | C14: ='10-11.Delivery Van Expense'!D2 -> 0
A15: 11 | B15: Delivery Van Maintenance | C15: ='10-11.Delivery Van Expense'!D13 -> 0
A16: 12 | B16: Entertainment | C16: ='12. Entertainment'!D2 -> 0
A17: 13 | B17: Food Allowance | C17: ='13. Food Allowance'!D2 -> 0
A18: 14 | B18: Conveyance | C18: ='14. Conveyance'!D2 -> 420 | D18: WH to WH, WH to HO, WH to Shop etc.
A19: 15 | B19: Security | C19: ='15. For Security'!D2 -> 0
B20: Total | C20: =SUM(C5:C19) -> 34900
C22: Unit | D22: Litre (L)
C23: B2B-IPP | D23: ='1. B2B- IPP'!D4 -> 0
C24: B2C | D24: ='2. B2C'!D4 -> 7845
C25: B2B-Non Power | D25: ='3. B2B-Non Power'!D4 -> 0
C26: Goods Transfer (Sending) | D26: ='4. Goods Sending Expense'!D4 -> 0
C27: Goods Import (Receiving) | D27: ='5. Goods Receiving Expense'!D4 -> 9218
C28: Total (L) | D28: =SUM(D23:D27) -> 17063
A37: Prepared By | B37: Checked By | C37: Line Manager | D37: Head of SCM
C43: _______________
A44: Dept. of F&A | C44: Internal Audit | D44: Approved By

Sheet 1. B2B- IPP
C1: B2B - IPP
H2: Delivey Person's Expense
A3: Date | B3: DO No. | C3: Customer Name | D3: Volume (L) | E3: Delivery Vehicle Charge (Tk.) | F3: Courier Charge (Tk.) | G3: Labour Charge | H3: Helper Name | I3: Conveyance | J3: Hotel Rent | K3: Food | L3: Others | M3: Total
D4: =SUM(D5:D100) -> 0 | E4: =SUM(E5:E100) -> 0 | F4: =SUM(F5:F100) -> 0 | G4: =SUM(G5:G100) -> 0 | H4: =SUM(H5:H100) -> 0 | I4: =SUM(I5:I100) -> 0 | J4: =SUM(J5:J100) -> 0 | K4: =SUM(K5:K100) -> 0 | L4: =SUM(L5:L100) -> 0 | M4: =SUM(E4,F4,G4,I4,J4,K4,L4) -> 0

Sheet 2. B2C
A1: B2C
G2: Delivey Person's Expense
A3: Date | B3: DO No. | C3: Customer Name | D3: Volume (L) | E3: Labour Cost | F3: Transport Cost | G3: Executive & Helper Name | H3: Helper Conveyance | I3: Hotel Rent | J3: Food | K3: Others | L3: Total
D4: =SUM(D5:D115) -> 7845 | E4: =SUM(E5:E113) -> 3060 | F4: =SUM(F5:F115) -> 29020 | H4: =SUM(H5:H115) -> 1070 | I4: =SUM(I6:I13) -> 0 | J4: =SUM(J6:J128) -> 200 | K4: =SUM(K6:K13) -> 0 | L4: =SUM(E4,F4,H4,I4,J4,) -> 33350
A5: 45647 | B5: 078377 | C5: Maa Auto Engineering & Service Center | D5: 27 | E5: 400 | F5: 4100 | G5: shah alam &sabir | L5: =SUM(F5:H5) -> 4100
A6: 45647 | B6: 078392 | C6: Alam brathers | D6: 569 | L6: =SUM(F6:H6) -> 0
A7: 45647 | B7: 078329 | C7: Sadia honda garage & servicing centre | D7: 13 | L7: =SUM(F7:H7) -> 0
A8: 45647 | B8: 078458 | C8: Sami Sadi Engineering | D8: 161 | F8: 650 | G8: shah alam | H8: 100 | L8: =SUM(F8:H8) -> 750
A9: 45648 | B9: 078410 | C9: Fatema Motors | D9: 1153 | E9: 400 | F9: 3800 | G9: shah alam &sabir | L9: =SUM(F9:H9) -> 3800
A10: 45649 | B10: 078568 | C10: MASUM MOTORS & WORKSHOP | D10: 13 | F10: 100 | G10: shah alam | H10: 100 | L10: =SUM(F10:H10) -> 200
A11: 45649 | B11: 078567 | C11: M/S Ma motors | D11: 39 | F11: 150 | G11: shah alam | H11: 30 | L11: =SUM(F11:H11) -> 180
A12: 45649 | B12: 78476 | C12: Fatema Motors | D12: 4 | F12: 180 | G12: shah alam | H12: 150 | L12: =SUM(F12:H12) -> 330
A13: 45649 | B13: 078585 | C13: Fatema Motors | D13: 33 | L13: =SUM(F13:H13) -> 0
A14: 45650 | B14: 078512 | C14: Ayesha Auto Mobiles | D14: 113 | F14: 1160 | G14: shah alam | H14: 220 | L14: =SUM(F14:H14) -> 1380
A15: 45650 | B15: 078670 | C15: M/S Ma motors | D15: 390 | E15: 60 | F15: 500 | G15: sohel | H15: 30 | L15: =SUM(F15:H15) -> 530
A16: 45652 | B16: 078679 | C16: Takiya motors | D16: 215 | E16: 500 | F16: 2200 | G16: shah alam & sabbir | L16: =SUM(F16:H16) -> 2200
A17: 45652 | B17: 078717 | C17: F Alam Motor | D17: 2 | L17: =SUM(F17:H17) -> 0
A18: 45652 | B18: 078336 | C18: M/S Hamim Motors | D18: 82 | F18: 960 | G18: shah alam | H18: 280 | L18: =SUM(F18:H18) -> 1240
A19: 45652 | B19: 078720 | C19: City Bike Shop & Servicing Center | D19: 27 | L19: =SUM(F19:H19) -> 0
A20: 45652 | B20: 078664 | C20: Mayar Dowa Honda Servicing Center | D20: 80 | L20: =SUM(F20:H20) -> 0
A21: 45652 | B21: 078718 | C21: Power Moto | D21: 2 | L21: =SUM(F21:H21) -> 0
A22: 45652 | B22: 078777 | C22: M/S Ma motors | D22: 696 | F22: 600 | G22: sohel & sabbir | L22: =SUM(F22:H22) -> 600
A23: 45652 | B23: 078783 | C23: Mamun Motors | D23: 2
A24: 45652 | B24: 078785 | C24: M/S ISLAM MOTORS | D24: 2
A25: 45653 | B25: 078639 | C25: MASUM MOTORS & WORKSHOP | D25: 13 | F25: 100 | G25: shah alam | H25: 100 | L25: =SUM(F25:H25) -> 200
A26: 45654 | B26: 078769 | C26: Fatema Motors | D26: 1153 | E26: 400 | F26: 3800 | G26: shah alam &sabir | L26: =SUM(F26:H26) -> 3800
A27: 45655 | B27: 078852 | C27: Asia Motors | D27: 26 | E27: 400 | F27: 120 | G27: shah alam | H27: 40 | L27: =SUM(F27:H27) -> 160
A28: 45655 | B28: 078896 | C28: M/S Ma motors | D28: 396 | F28: 500 | G28: shah alam & tanbir | H28: 20 | L28: =SUM(F28:H28) -> 520
A29: 45656 | B29: 078912 | C29: Biker Choice | D29: 40 | E29: 400 | F29: 5100 | G29: shah alam & tanbir | J29: 100 | L29: =SUM(F29:H29) -> 5100
A30: 45656 | B30: 078652 | C30: B K Traders and Motors Prats | D30: 200 | L30: =SUM(F30:H30) -> 0
A31: 45656 | B31: 078880 | C31: M A Enterprise | D31: 400 | L31: =SUM(F31:H31) -> 0
A32: 45656 | B32: 078887 | C32: M A Enterprise | D32: 66 | L32: =SUM(F32:H32) -> 0
A33: 45657 | B33: 79008 | C33: M/S Sahalam Motors | D33: 215 | E33: 500 | F33: 5000 | G33: shah alam & tanbir | J33: 100 | L33: =SUM(F33:H33) -> 5000
A34: 45657 | B34: 078859 | C34: Alam brathers | D34: 1640 | L34: =SUM(F34:H34) -> 0
A35: 45657 | B35: 078857 | C35: Alam brathers | D35: 50 | L35: =SUM(F35:H35) -> 0
A36: 45657 | B36: 079024 | C36: Garda Shield Security Serviece Ltd | D36: 23 | L36: =SUM(F36:H36) -> 0
L37: =SUM(F37:H37) -> 0
L38: =SUM(F38:H38) -> 0
L39: =SUM(F39:H39) -> 0
L62: =SUM(F62+H62) -> 0
...

Sheet 4. Goods Sending Expense
A1: Goods Transfer_Sending
G2: Delivey Person's Expense
A3: Date | B3: DO No. | C3: Customer Name | D3: Volume (L) | E3: Labour Cost | F3: Transport Cost | G3: Helper Name | H3: Helper Conveyance | I3: Hotel Rent | J3: Food | K3: Others | L3: Total
D4: =SUM(D5:D100) -> 0 | E4: =SUM(E5:E100) -> 0 | F4: =SUM(F5:F100) -> 0 | H4: =SUM(H5:H100) -> 0 | I4: =SUM(I5:I100) -> 0 | J4: =SUM(J5:J100) -> 0 | K4: =SUM(K5:K100) -> 0 | L4: =SUM(E4,F4,H4,I4,J4,K4) -> 0

Sheet 3. B2B-Non Power
A1: B2B Non Power
G2: Delivey Person's Expense
A3: Date | B3: DO No. | C3: Customer Name | D3: Volume (L) | E3: Labour Cost | F3: Transport Cost | G3: Helper Name | H3: Helper Conveyance | I3: Hotel Rent | J3: Food | K3: Others | L3: Total
D4: =SUM(D5:D100) -> 0 | E4: =SUM(E5:E100) -> 0 | F4: =SUM(F5:F100) -> 0 | H4: =SUM(H5:H100) -> 0 | I4: =SUM(I5:I100) -> 0 | J4: =SUM(J5:J100) -> 0 | K4: =SUM(K5:K100) -> 0 | L4: =SUM(H4:K4,F4,E4) -> 0

Sheet Goods Delivery Voucher
A1: Ranks Petroleum Limited | I1: Ranks Petroleum Limited
A3: Employee Name: | C3: shanto,sohel,arif,shah alam | F3: Position: | G3: Helper | I3: Employee Name: | K3: Palash | N3: Position: | O3: Helper
A5: Sl. No. | B5: Date | C5: From | D5: To | E5: Purpose/DO | F5: Via | G5: Amount | I5: Sl. No. | J5: Date | K5: From | L5: To | M5: Purpose/DO | N5: Via | O5: Amount
A6: 1 | B6: 45647 | C6: depot | D6: Beside fair service,Kachua,Stadium market,Sadar,Chandpur. | E6: delivery | F6: truck | G6: 4100
A7: =SUM(A6+1) -> 2 | B7: 45647 | C7: depot | D7: Gowripur Bus stand, daudkandi, comilla | E7: delivery | F7: bus,auto,cng | G7: 650
A8: =SUM(A7+1) -> 3 | B8: 45648 | C8: depot | D8: Academy Road,Gudam Quater,Feni. | E8: delivery | F8: truck | G8: 3800
A9: =SUM(A8+1) -> 4 | B9: 45649 | C9: depot | D9: west side CNG pump, eliyetgonj, Doudkandi | E9: delivery | F9: bus,auto,cng | G9: 100
A10: =SUM(A9+1) -> 5 | B10: 45649 | C10: depot | D10: mozumder market, poddar bazar bishoroad | E10: delivery | F10: bus,auto,cng | G10: 150
A11: =SUM(A10+1) -> 6 | B11: 45649 | C11: depot | D11: Academy Road,Gudam Quater,Feni. | E11: delivery | F11: bus,auto,cng | G11: 180
A12: =SUM(A11+1) -> 7 | B12: 45650 | C12: depot | D12: Banshgari Steel Bridge, Bancharampur, B-Baria | E12: delivery | F12: bus,auto,cng | G12: 1160
B13: 45650 | C13: depot | D13: mozumder market, poddar bazar bishoroad | E13: delivery | F13: truck | G13: 500
A14: =SUM(A12+1) -> 8 | B14: 45652 | C14: depot | D14: Bilbari,Hajigonj, Chandpu | E14: delivery | F14: bus,auto,cng | G14: 2200
A15: =SUM(A14+1) -> 9 | B15: 45652 | C15: depot | D15: North themoni,Sadar,New bus Tarminal,sadar,aypas road,beside City plaz,Ramgonj,College get,Sonapur,Lakshimpur | E15: delivery | F15: bus,auto,cng | G15: 960
A16: =SUM(A15+1) -> 10 | B16: 45652 | C16: depot | D16: Mozumder market, foyjoner Nessa mention,poddar bazar bishoroad | E16: delivery | F16: bus,auto,cng | G16: 600
A17: =SUM(A16+1) -> 11 | B17: 45653 | C17: depot | D17: west side CNG pump, eliyetgonj, Doudkandi | E17: delivery | F17: bus,auto,cng | G17: 100
A18: =SUM(A17+1) -> 12 | B18: 45654 | C18: depot | D18: Academy Road,Gudam Quater,Feni. | E18: delivery | F18: truck | G18: 3800
A19: =SUM(A18+1) -> 13 | B19: 45655 | C19: depot | D19: Jangaliya, cumilla | E19: delivery | F19: bus,auto,cng | G19: 120
A20: =SUM(A19+1) -> 14 | B20: 45655 | C20: depot | D20: Mozumder market, poddar bazar bishoroad | E20: delivery | F20: van | G20: 500
A21: =SUM(A20+1) -> 15 | B21: 45656 | C21: depot | D21: kasba, Medda. Sadar,ashuganjb baria , | E21: delivery | F21: truck | G21: 5100
A22: =SUM(A21+1) -> 16 | B22: 45657 | C22: depot | D22: um market,Sadar,Chandpur. | E22: delivery | F22: truck | G22: 5000
F25: Total | G25: =SUM(G6:G22) -> 29020
I27: …................. | L27: …..................... | N27: …......................
I28: Prepared By | L28: In-charge | N28: Checked By
A29: …................. | D29: …..................... | F29: …......................
A30: Prepared By | D30: In-charge | F30: Checked By

Sheet Conveyance Voucher
A1: Ranks Petroleum Limited | I1: Ranks Petroleum Limited
A3: Employee Name: | C3: shah alam & sohel | F3: Position: | G3: Helper | I3: Employee Name: | K3: arif | N3: Position: | O3: Executive
A5: Sl. No. | B5: Date | C5: From | D5: To | E5: Purpose | F5: Via | G5: Amount | I5: Sl. No. | J5: Date | K5: From | L5: To | M5: Purpose | N5: Via | O5: Amount
A6: 1 | B6: 45346 | C6: mozumder market, poddar bazar bishoroad | D6: depot | E6: delivery | F6: bus,auto,cng | G6: 30 | I6: 1 | J6: 44964 | K6: shoyagazi,cumilla | L6: depot | M6: delivery | N6: bus,auto | O6: 60
I8: …................. | L8: …..................... | N8: …......................
F9: Total | G9: =SUM(G6:G6) -> 30 | I9: Prepared By | L9: In-charge | N9: Checked By
A11: …................. | D11: …..................... | F11: …...................... | I11: Ranks Petroleum Limited
A12: Prepared By | D12: In-charge | F12: Checked By
I13: Employee Name: | K13: dipok | N13: Position: | O13: Helper
A14: Ranks Petroleum Limited
I15: Sl. No. | J15: Date | K15: From | L15: To | M15: Purpose | N15: Via | O15: Amount
A16: Employee Name: | C16: shah alam | F16: Position: | G16: helper | I16: 1 | J16: 45202 | K16: b-bariya,tinlack pir,kosba | L16: depot | M16: delivery | N16: bus,auto,cng
I17: 2 | J17: 45203 | K17: police fari cumilla | L17: depot | M17: delivery | N17: auto
A18: Sl. No. | B18: Date | C18: From | D18: To | E18: Purpose | F18: Via | G18: Amount
A19: 1 | B19: 45647 | C19: Gowripur Bus stand, daudkandi, comilla | D19: depot | E19: delivery | F19: bus,auto | G19: 100 | N19: Total
A20: 2 | B20: 45649 | C20: west side CNG pump, eliyetgonj, Doudkandi | D20: depot | E20: delivery | F20: bus,auto | G20: 100
A21: 3 | B21: 45649 | C21: mozumder market, poddar bazar bishoroad | D21: depot | E21: delivery | F21: bus,auto | G21: 30
A22: 4 | B22: 45649 | C22: Academy Road,Gudam Quater,Feni. | D22: depot | E22: delivery | F22: bus,auto | G22: 150
A23: 5 | B23: 45650 | C23: Banshgari Steel Bridge, Bancharampur, B-Baria | D23: depot | E23: delivery | F23: bus,auto | G23: 220
A24: 6 | B24: 45652 | C24: City plaz,Ramgonj,College get,Sonapur,Lakshimpur | D24: depot | E24: delivery | F24: bus,auto | G24: 280
A25: 7 | B25: 45653 | C25: west side CNG pump, eliyetgonj, Doudkandi | D25: depot | E25: delivery | F25: bus,auto | G25: 100
A26: 8 | B26: 45655 | C26: Jangaliya, cumilla | D26: depot | E26: delivery | F26: bus,auto | G26: 40
A27: 9 | B27: 45655 | C27: Mozumder market, poddar bazar bishoroad | D27: depot | E27: delivery | F27: bus,auto | G27: 20
I28: Prepared By | L28: In-charge | N28: Checked By
F29: Total | G29: =SUM(G19:G27) -> 1040
I31: Ranks Petroleum Limited
A32: …................. | D32: …..................... | F32: …...................... | I32: conveyance
A33: Prepared By | D33: In-charge | F33: Checked By | I33: Employee Name: | K33: arif | N33: Position: | O33: Executive
A35: Ranks Petroleum Limited | I35: Sl. No. | J35: Date | K35: From | L35: To | M35: Purpose | N35: Via | O35: Amount
I36: 1
A37: Employee Name: | F37: Position: | G37: Helper | I37: 2
A39: Sl. No. | B39: Date | C39: From | D39: To | E39: Purpose | F39: Via | G39: Amount
N41: Total | O41: =SUM(O36:O39) -> 0
G44: =SUM(G40:G43) -> 0 | I44: …................. | L44: …..................... | N44: …......................
I45: Prepared By | L45: In-charge | N45: Checked By
A47: …................. | D47: …..................... | F47: …......................
A48: Prepared By | D48: In-charge | F48: Checked By
A50: Ranks Petroleum Limited
A52: Employee Name: | C52: arif | F52: Position: | G52: Executive
A54: Sl. No. | B54: Date | C54: From | D54: To | E54: Purpose | F54: Via | G54: Amount
...

Sheet 5. Goods Receiving Expense
A1: Goods Receiving
G2: Delivey Person's Expense
A3: Date | B3: TO No. | C3: Customer Name | D3: Volume (L) | E3: Labour Cost | F3: Transport Cost | G3: Helper Name | H3: Helper Conveyance | I3: Hotel Rent | J3: Food | K3: Others | L3: Total
D4: =SUM(D5:D101) -> 9218 | E4: =SUM(E5:E101) -> 600 | F4: =SUM(F6:F101) -> 140 | H4: =SUM(H6:H101) -> 40 | I4: =SUM(I6:I101) -> 0 | J4: =SUM(J5:J101) -> 310 | K4: =SUM(K6:K101) -> 0 | L4: =SUM(E4,F4,H4,I4,J4,K4) -> 1090
A5: 45647 | B5: 8928 | C5: cumilla depot | D5: 5943 | E5: 400 | G5: shah alam & sabbir | J5: 160
A6: 45655 | B6: 8957 | C6: cumilla depot | D6: 3060 | E6: 200 | G6: shah alam & tanbir | J6: 150
A7: 45655 | B7: 8958 | C7: cumilla depot | D7: 80
A8: 45657 | B8: 8975 | C8: cumilla depot | D8: 45 | F8: 140 | G8: shah alam | H8: 40
A9: 45657 | B9: 8971 | C9: cumilla depot | D9: 90

Sheet 6.WH-Depot Maintenance
B1: WH/Depot Maintenance
C3: Total | D3: =SUM(D5:D37) -> 40
A4: Date | B4: Description | C4: Purpose | D4: Amount | E4: Remarks
A5: 45652 | B5: courier | C5: depot | D5: 40

Sheet 7. Utilities
B1: Utilities Expense
C2: Total | F2: =SUM(F4:F5) -> 0
A3: Date | B3: Utility Type | C3: Billing Month | F3: Amount | G3: Remarks
A4: 23/12/2023 to 31/1/2023 | B4: Electricity bill | C4: 44957 | D4: Previous unit-935,current unit-1008 | E4: 73 unit | G4: one month
A5: 1-12-2023 T0 1-1-2024 | B5: water bill | C5: 44957 | G5: one month
F9: Received

Sheet 8. Printing
A1: Printing Expense
D2: Total | E2: =SUM(E4:E25) -> 0
A3: Date | B3: Description | C3: Purpose | D3: Qty | E3: Amount | F3: Remarks

Sheet 9. Stationary
B1: Stationary Expense
D2: Total | E2: =SUM(E4:E23) -> 0
A3: Date | B3: Description | C3: Purpose | D3: Qty | E3: Amount | F3: Remarks

Sheet 10-11.Delivery Van Expense
A1: Delivery Van Fuel & Lubricants
C2: Total | D2: =SUM(D4:D9) -> 0
A3: Date | B3: Desription | C3: Qty | D3: Amount | E3: Remarks
A12: Delivery Van Maintenance
C13: Total | D13: =SUM(D15:D25) -> 0
A14: Date | B14: Desription | C14: Qty | D14: Amount | E14: Remarks

Sheet 12. Entertainment
A1: Entertainment
C2: Total | D2: =SUM(D4:D16) -> 0
A3: Date | B3: Description | C3: Purpose | D3: Amount | E3: Remarks

Sheet 13. Food Allowance
A1: Food Allowance
C2: Total | D2: =SUM(D4:D30) -> 0
A3: Duration/Date | B3: Employee Name | C3: Day | D3: Amount | E3: Remarks

Sheet 14. Conveyance
A1: Conveyance
C2: Total | D2: =SUM(D4:D36) -> 420
A3: Duration/Date | B3: Employee Name | C3: Purpose | D3: Amount | E3: Remarks
A4: 45652 | B4: sohel | C4: depot | D4: 50 | E4: petty cash bill
A5: 45655 | B5: shah alam | C5: depot | D5: 220 | E5: 2 carton jacket
A6: 45657 | B6: shah alam | C6: depot | D6: 150 | E6: 3 carton jacket
C13: S

Sheet 15. For Security
A1: Expense for Security Purpose
C2: Total | D2: =SUM(D4:D30) -> 0
A3: Date | B3: Employee Name | C3: Purpose | D3: Amount | E3: Remarks

Sheet Monthly Volume
W1: Daily Basis Delivered & Received Volume (L)
B2: Month Name:
B3: Item | C3: 1 | D3: 2 | E3: 3 | F3: 4 | G3: 5 | H3: 6 | I3: 7 | J3: 8 | K3: 9 | L3: 10 | M3: 11 | N3: 12 | O3: 13 | P3: 14 | Q3: 15 | R3: 16 | S3: 17 | T3: 18 | U3: 19 | V3: 20 | W3: 21 | X3: 22 | Y3: 23 | Z3: 24 | AA3: 25 | AB3: 26 | AC3: 27 | AD3: 28 | AE3: 29 | AF3: 30 | AG3: 31 | AH3: Total
B4: B2B IPP | AH4: =SUM(C4:AG4) -> 0
B5: B2C
B6: B2B- Non Power
B7: Goods Transfer (Sending)
B8: Goods Transfer (Received)
C9: =SUM(C4:C8) -> 0 | D9: =SUM(D4:D8) -> 0 | E9: =SUM(E4:E8) -> 0 | F9: =SUM(F4:F8) -> 0 | G9: =SUM(G4:G8) -> 0 | H9: =SUM(H4:H8) -> 0 | I9: =SUM(I4:I8) -> 0 | J9: =SUM(J4:J8) -> 0 | ... Q9: =SUM(Q4:Q8) -> 0

Sheet Purchase Voucher
A1: Ranks Petroleum Limited | G1: Ranks Petroleum Limited
A3: WH/Depot Name: | C3: Bogura | G3: WH/Depot Name:Cumilla
A5: Sl. No. | B5: Date | C5: Description | D5: Qty | E5: Amount | G5: Sl. No. | H5: Date | I5: Description | J5: Qty | K5: Amount
A6: 1 | G6: 1
A7: 2
A8: 3 | G8: Total
A9: 4
A10: 5
A11: 6 | G11: …................. | I11: …..................... | J11: …......................
A12: Total | E12: =SUM(E6:E11) -> 0 | G12: Prepared By | I12: In-charge | J12: Checked By
A15: …................. | C15: …..................... | D15: …...................... | G15: Ranks Petroleum Limited
A16: Prepared By | C16: In-charge | D16: Checked By
G17: WH/Depot Name:
A19: Ranks Petroleum Limited | G19: Sl. No. | H19: Date | I19: Description | J19: Qty | K19: Amount
G20: 1
A21: WH/Depot Name: | G21: 2
G22: 3
A23: Sl. No. | B23: Date | C23: Description | D23: Qty | E23: Amount | G23: 4
A24: 1 | G24: 5
A25: 2 | G25: 6
A26: 3 | G26: Total
A27: 4
A28: 5
A29: 6
A30: Total | G30: …................. | I30: …..................... | J30: …......................
G31: Prepared By | I31: In-charge | J31: Checked By
A34: …................. | C34: …..................... | D34: …......................
A35: Prepared By | C35: In-charge | D35: Checked By

Sheet Labour Bill Voucher
A1: Ranks Petroleum Limited | H1: Ranks Petroleum Limited
C2: Labour Bill | J2: Food Bill After Work
A3: Sl. No. | B3: Date | C3: TO Number | D3: Purpose | E3: Amount | F3: Labour Signature | H3: Sl. No. | I3: Date | J3: Description | K3: Purpose | L3: Amount | M3: Remaks
A4: 1 | B4: 45647 | C4: 8928 | D4: delivery | E4: 400 | H4: 1 | I4: 45656 | J4: delivery | K4: depot | L4: 100 | M4: 3 person food
A5: 2 | B5: 45655 | C5: 8957,8958 | D5: delivery | E5: 200 | H5: 2 | I5: 45656 | J5: delivery | K5: depot | L5: 100 | M5: 3 person food
K6: Total | L6: =SUM(L4:L5) -> 200
D7: Total | E7: =SUM(E4:E6) -> 600
H9: …................. | K9: …..................... | M9: …......................
A10: …................. | D10: …..................... | F10: …...................... | H10: Prepared By | K10: In-charge | M10: Checked By
A11: Prepared By | D11: In-charge | F11: Checked By
H12: Ranks Petroleum Limited
J13: Expense for Security Purpose
A14: Ranks Petroleum Limited
C15: Food Bill After Work | H15: Date | J15: Employee Name | K15: purpose | L15: Amount
A16: Sl. No. | B16: Date | C16: Description | D16: Purpose | E16: Amount | F16: Remaks
A17: 1 | B17: 45647 | C17: unloading | D17: depot | E17: 160 | F17: 5 person food
A18: 2 | B18: 45655 | C18: unloading | D18: depot | E18: 150 | F18: 4 person food | K18: Total | L18: 500
D19: Total | E19: =SUM(E17:E17) -> 160
A22: …................. | D22: …..................... | F22: …...................... | H22: …................. | J22: …..................... | L22: …......................
A23: Prepared By | D23: In-charge | F23: Checked By | H23: Prepared By | J23: In-charge | L23: Checked By
A25: Ranks Petroleum Limited
C26: Day Labour Bill
A27: Sl. No. | B27: Date | C27: DO Number | D27: Purpose | E27: Amount | F27: Labour Signature
A28: 1 | B28: 45647 | C28: 78377,78392,78329,78458 | D28: delivery | E28: 400
A29: 2 | B29: 45648 | C29: 7840 | D29: delivery | E29: 400
A30: 3 | B30: 45650 | C30: 78670 | D30: delivery | E30: 60
A31: 4 | B31: 45652 | C31: 78679,78717,78336,78664,78718,78718,78777, | D31: delivery | E31: 500
A32: 5 | B32: 45654 | C32: 78769 | D32: delivery | E32: 400
A33: 6 | B33: 45655 | C33: 78852,78896 | D33: delivery | E33: 400
A34: 7 | B34: 45656 | C34: 78912,78652,78880,7887 | D34: delivery | E34: 400
A35: 8 | B35: 45657 | C35: 79008,78859,78857,79024 | D35: delivery | E35: 500
D37: Total | E37: =SUM(E28:E36) -> 3060
A40: …................. | D40: …..................... | F40: …......................
A41: Prepared By | D41: In-charge | F41: Checked By
C45: Due to the resignation of an employee, we appoint a temporary day-based helper to ensure the continuity of office work.

Sheet Others & Cleaning
A1: Bill (Others) | F1: Cleaning Bill
A2: Bogra Depot | F2: Bogra Depot
A4: SL. No. | B4: Date | C4: Description | D4: Amount (BDT)
A5: 1
A6: 2 | F6: SL. No. | G6: Date | H6: Description | I6: Amount (BDT)
A7: 3 | F7: 1
A8: 4 | F8: 2
A9: 5 | F9: 3
A10: 5 | F10: 4
A11: 6 | F11: 5
A12: 7 | F12: Total
A13: Total | D13: =SUM(D5:D12) -> 0
B15: Note: | C15: For cctv camera wiring
A16: Electrician Name: | B16: Md. Tariqul
A17: Mobile No: | B17: 01796431852
F18: Service Provider Name: | H18: Rahim
A20: Depot Incharge | C20: Line Manager
F22: Depot Incharge | H22: Line Manager
A23: Bill (Others)
A24: Bogra Depot
A26: SL. No. | B26: Date | C26: Description | D26: Amount (BDT)
A27: 1 | B27: 44927 | C27: Van hire to bring furniture | D27: 200
A28: 2
A29: 3
A30: 4
A31: 5
A32: 6
A33: 7
A34: Total | D34: =SUM(D27:D33) -> 200
A38: Van Driver Name: | B38: Abdur Rahim
A39: Mobile No: | B39: 01942-743481
A45: Depot Incharge | C45: Line Manager

Sheet Food Bill
A1: Food Bill (After Hours ) | H1: Food Bill (After Hours / Holiday)
A2: Bogra Depot | H2: Bogra Depot
H4: SL. No. | I4: Date | J4: Name | K4: Time | L4: Description | M4: Amount (BDT)
H5: 1
A6: SL. No. | B6: Date | C6: Name | D6: Time | E6: Description | F6: Amount (BDT) | H6: 2
A7: 1 | H7: Total
A8: 2
A9: Total
B14: Employee | D14: Depot Incharge | F14: Line Manager | H14: Employee | J14: Depot Incharge | M14: Line Manager
